[2022-03-14 17:38:19,606] {taskinstance.py:670} INFO - Dependencies all met for <TaskInstance: twitter_dag.twitter_bbb22 2022-03-11T09:00:00+00:00 [queued]>
[2022-03-14 17:38:19,611] {taskinstance.py:670} INFO - Dependencies all met for <TaskInstance: twitter_dag.twitter_bbb22 2022-03-11T09:00:00+00:00 [queued]>
[2022-03-14 17:38:19,611] {taskinstance.py:880} INFO - 
--------------------------------------------------------------------------------
[2022-03-14 17:38:19,611] {taskinstance.py:881} INFO - Starting attempt 1 of 1
[2022-03-14 17:38:19,611] {taskinstance.py:882} INFO - 
--------------------------------------------------------------------------------
[2022-03-14 17:38:19,617] {taskinstance.py:901} INFO - Executing <Task(TwitterOperator): twitter_bbb22> on 2022-03-11T09:00:00+00:00
[2022-03-14 17:38:19,619] {standard_task_runner.py:54} INFO - Started process 24596 to run task
[2022-03-14 17:38:19,650] {standard_task_runner.py:77} INFO - Running: ['airflow', 'run', 'twitter_dag', 'twitter_bbb22', '2022-03-11T09:00:00+00:00', '--job_id', '43', '--pool', 'default_pool', '--raw', '-sd', 'DAGS_FOLDER/twitter_dag.py', '--cfg_path', '/tmp/tmpq9cee_zr']
[2022-03-14 17:38:19,650] {standard_task_runner.py:78} INFO - Job 43: Subtask twitter_bbb22
[2022-03-14 17:38:19,666] {logging_mixin.py:112} INFO - Running <TaskInstance: twitter_dag.twitter_bbb22 2022-03-11T09:00:00+00:00 [running]> on host 1a222f561522
[2022-03-14 17:38:19,701] {base_hook.py:89} INFO - Using connection to: id: twitter_default. Host: https://api.twitter.com, Port: None, Schema: None, Login: None, Password: None, extra: XXXXXXXX
[2022-03-14 17:38:19,702] {twitter_hook.py:37} INFO - URL: https://api.twitter.com/2/tweets/search/recent?query=jade&tweet.fields=author_id,conversation_id,created_at,id,in_reply_to_user_id,public_metrics,text&expansions=author_id&user.fields=id,name,username,created_at&start_time=2022-03-11T09:00:00.00Z&end_time=2022-03-12T09:00:00.00Z
[2022-03-14 17:38:19,723] {logging_mixin.py:112} WARNING - /run/datapipeline/.env/lib/python3.8/site-packages/urllib3/connectionpool.py:981: InsecureRequestWarning: Unverified HTTPS request is being made to host 'api.twitter.com'. Adding certificate verification is strongly advised. See: https://urllib3.readthedocs.io/en/latest/advanced-usage.html#ssl-warnings
  warnings.warn(
[2022-03-14 17:38:19,868] {http_hook.py:150} ERROR - HTTP error: Too Many Requests
[2022-03-14 17:38:19,868] {http_hook.py:151} ERROR - {"title":"Too Many Requests","detail":"Too Many Requests","type":"about:blank","status":429}
[2022-03-14 17:38:19,870] {taskinstance.py:1150} ERROR - 429:Too Many Requests
Traceback (most recent call last):
  File "/run/datapipeline/.env/lib/python3.8/site-packages/airflow/hooks/http_hook.py", line 148, in check_response
    response.raise_for_status()
  File "/run/datapipeline/.env/lib/python3.8/site-packages/requests/models.py", line 941, in raise_for_status
    raise HTTPError(http_error_msg, response=self)
requests.exceptions.HTTPError: 429 Client Error: Too Many Requests for url: https://api.twitter.com/2/tweets/search/recent?query=jade&tweet.fields=author_id,conversation_id,created_at,id,in_reply_to_user_id,public_metrics,text&expansions=author_id&user.fields=id,name,username,created_at&start_time=2022-03-11T09:00:00.00Z&end_time=2022-03-12T09:00:00.00Z

During handling of the above exception, another exception occurred:

Traceback (most recent call last):
  File "/run/datapipeline/.env/lib/python3.8/site-packages/airflow/models/taskinstance.py", line 984, in _run_raw_task
    result = task_copy.execute(context=context)
  File "/run/datapipeline/airflow/plugins/operators/twitter_operator.py", line 50, in execute
    for pg in hook.run():
  File "/run/datapipeline/airflow/plugins/hooks/twitter_hook.py", line 55, in run
    yield from self.paginate(url, session)
  File "/run/datapipeline/airflow/plugins/hooks/twitter_hook.py", line 45, in paginate
    data = self.connect_to_endpoint(full_url, session)
  File "/run/datapipeline/airflow/plugins/hooks/twitter_hook.py", line 38, in connect_to_endpoint
    return self.run_and_check(session, prep, {}).json()
  File "/run/datapipeline/.env/lib/python3.8/site-packages/airflow/hooks/http_hook.py", line 181, in run_and_check
    self.check_response(response)
  File "/run/datapipeline/.env/lib/python3.8/site-packages/airflow/hooks/http_hook.py", line 152, in check_response
    raise AirflowException(str(response.status_code) + ":" + response.reason)
airflow.exceptions.AirflowException: 429:Too Many Requests
[2022-03-14 17:38:19,871] {taskinstance.py:1187} INFO - Marking task as FAILED. dag_id=twitter_dag, task_id=twitter_bbb22, execution_date=20220311T090000, start_date=20220314T173819, end_date=20220314T173819
[2022-03-14 17:38:24,603] {local_task_job.py:102} INFO - Task exited with return code 1
[2022-03-14 18:34:12,270] {taskinstance.py:670} INFO - Dependencies all met for <TaskInstance: twitter_dag.twitter_bbb22 2022-03-11T09:00:00+00:00 [queued]>
[2022-03-14 18:34:12,276] {taskinstance.py:670} INFO - Dependencies all met for <TaskInstance: twitter_dag.twitter_bbb22 2022-03-11T09:00:00+00:00 [queued]>
[2022-03-14 18:34:12,276] {taskinstance.py:880} INFO - 
--------------------------------------------------------------------------------
[2022-03-14 18:34:12,276] {taskinstance.py:881} INFO - Starting attempt 1 of 1
[2022-03-14 18:34:12,276] {taskinstance.py:882} INFO - 
--------------------------------------------------------------------------------
[2022-03-14 18:34:12,281] {taskinstance.py:901} INFO - Executing <Task(TwitterOperator): twitter_bbb22> on 2022-03-11T09:00:00+00:00
[2022-03-14 18:34:12,283] {standard_task_runner.py:54} INFO - Started process 7893 to run task
[2022-03-14 18:34:12,313] {standard_task_runner.py:77} INFO - Running: ['airflow', 'run', 'twitter_dag', 'twitter_bbb22', '2022-03-11T09:00:00+00:00', '--job_id', '57', '--pool', 'default_pool', '--raw', '-sd', 'DAGS_FOLDER/twitter_dag.py', '--cfg_path', '/tmp/tmp59jl559h']
[2022-03-14 18:34:12,314] {standard_task_runner.py:78} INFO - Job 57: Subtask twitter_bbb22
[2022-03-14 18:34:12,329] {logging_mixin.py:112} INFO - Running <TaskInstance: twitter_dag.twitter_bbb22 2022-03-11T09:00:00+00:00 [running]> on host 1a222f561522
[2022-03-14 18:34:12,360] {base_hook.py:89} INFO - Using connection to: id: twitter_default. Host: https://api.twitter.com, Port: None, Schema: None, Login: None, Password: None, extra: XXXXXXXX
[2022-03-14 18:34:12,362] {twitter_hook.py:37} INFO - URL: https://api.twitter.com/2/tweets/search/recent?query=jade&tweet.fields=author_id,conversation_id,created_at,id,in_reply_to_user_id,public_metrics,text&expansions=author_id&user.fields=id,name,username,created_at&start_time=2022-03-11T09:00:00.00Z&end_time=2022-03-12T09:00:00.00Z
[2022-03-14 18:34:12,382] {logging_mixin.py:112} WARNING - /run/datapipeline/.env/lib/python3.8/site-packages/urllib3/connectionpool.py:981: InsecureRequestWarning: Unverified HTTPS request is being made to host 'api.twitter.com'. Adding certificate verification is strongly advised. See: https://urllib3.readthedocs.io/en/latest/advanced-usage.html#ssl-warnings
  warnings.warn(
[2022-03-14 18:34:12,540] {http_hook.py:150} ERROR - HTTP error: Too Many Requests
[2022-03-14 18:34:12,540] {http_hook.py:151} ERROR - {"title":"Too Many Requests","detail":"Too Many Requests","type":"about:blank","status":429}
[2022-03-14 18:34:12,542] {taskinstance.py:1150} ERROR - 429:Too Many Requests
Traceback (most recent call last):
  File "/run/datapipeline/.env/lib/python3.8/site-packages/airflow/hooks/http_hook.py", line 148, in check_response
    response.raise_for_status()
  File "/run/datapipeline/.env/lib/python3.8/site-packages/requests/models.py", line 941, in raise_for_status
    raise HTTPError(http_error_msg, response=self)
requests.exceptions.HTTPError: 429 Client Error: Too Many Requests for url: https://api.twitter.com/2/tweets/search/recent?query=jade&tweet.fields=author_id,conversation_id,created_at,id,in_reply_to_user_id,public_metrics,text&expansions=author_id&user.fields=id,name,username,created_at&start_time=2022-03-11T09:00:00.00Z&end_time=2022-03-12T09:00:00.00Z

During handling of the above exception, another exception occurred:

Traceback (most recent call last):
  File "/run/datapipeline/.env/lib/python3.8/site-packages/airflow/models/taskinstance.py", line 984, in _run_raw_task
    result = task_copy.execute(context=context)
  File "/run/datapipeline/airflow/plugins/operators/twitter_operator.py", line 50, in execute
    for pg in hook.run():
  File "/run/datapipeline/airflow/plugins/hooks/twitter_hook.py", line 55, in run
    yield from self.paginate(url, session)
  File "/run/datapipeline/airflow/plugins/hooks/twitter_hook.py", line 45, in paginate
    data = self.connect_to_endpoint(full_url, session)
  File "/run/datapipeline/airflow/plugins/hooks/twitter_hook.py", line 38, in connect_to_endpoint
    return self.run_and_check(session, prep, {}).json()
  File "/run/datapipeline/.env/lib/python3.8/site-packages/airflow/hooks/http_hook.py", line 181, in run_and_check
    self.check_response(response)
  File "/run/datapipeline/.env/lib/python3.8/site-packages/airflow/hooks/http_hook.py", line 152, in check_response
    raise AirflowException(str(response.status_code) + ":" + response.reason)
airflow.exceptions.AirflowException: 429:Too Many Requests
[2022-03-14 18:34:12,543] {taskinstance.py:1187} INFO - Marking task as FAILED. dag_id=twitter_dag, task_id=twitter_bbb22, execution_date=20220311T090000, start_date=20220314T183412, end_date=20220314T183412
[2022-03-14 18:34:17,268] {local_task_job.py:102} INFO - Task exited with return code 1
