[2022-03-03 19:33:30,614] {taskinstance.py:670} INFO - Dependencies all met for <TaskInstance: twitter_dag.twitter_bbb22 2022-02-26T09:00:00+00:00 [queued]>
[2022-03-03 19:33:30,619] {taskinstance.py:670} INFO - Dependencies all met for <TaskInstance: twitter_dag.twitter_bbb22 2022-02-26T09:00:00+00:00 [queued]>
[2022-03-03 19:33:30,620] {taskinstance.py:880} INFO - 
--------------------------------------------------------------------------------
[2022-03-03 19:33:30,620] {taskinstance.py:881} INFO - Starting attempt 1 of 1
[2022-03-03 19:33:30,620] {taskinstance.py:882} INFO - 
--------------------------------------------------------------------------------
[2022-03-03 19:33:30,625] {taskinstance.py:901} INFO - Executing <Task(TwitterOperator): twitter_bbb22> on 2022-02-26T09:00:00+00:00
[2022-03-03 19:33:30,628] {standard_task_runner.py:54} INFO - Started process 6549 to run task
[2022-03-03 19:33:30,660] {standard_task_runner.py:77} INFO - Running: ['airflow', 'run', 'twitter_dag', 'twitter_bbb22', '2022-02-26T09:00:00+00:00', '--job_id', '29', '--pool', 'default_pool', '--raw', '-sd', 'DAGS_FOLDER/twitter_dag.py', '--cfg_path', '/tmp/tmp84ypy_iz']
[2022-03-03 19:33:30,660] {standard_task_runner.py:78} INFO - Job 29: Subtask twitter_bbb22
[2022-03-03 19:33:30,675] {logging_mixin.py:112} INFO - Running <TaskInstance: twitter_dag.twitter_bbb22 2022-02-26T09:00:00+00:00 [running]> on host 1a222f561522
[2022-03-03 19:33:30,707] {base_hook.py:89} INFO - Using connection to: id: twitter_default. Host: https://api.twitter.com, Port: None, Schema: None, Login: None, Password: None, extra: XXXXXXXX
[2022-03-03 19:33:30,708] {twitter_hook.py:36} INFO - URL: https://api.twitter.com/2/tweets/search/recent?query=jade&tweet.fields=author_id,conversation_id,created_at,id,in_reply_to_user_id,public_metrics,text&expansions=author_id&user.fields=id,name,username,created_at&start_time=2022-02-26T09:00:00.00Z&end_time=2022-02-27T09:00:00.00Z
[2022-03-03 19:33:30,729] {logging_mixin.py:112} WARNING - /run/datapipeline/.env/lib/python3.8/site-packages/urllib3/connectionpool.py:981: InsecureRequestWarning: Unverified HTTPS request is being made to host 'api.twitter.com'. Adding certificate verification is strongly advised. See: https://urllib3.readthedocs.io/en/latest/advanced-usage.html#ssl-warnings
  warnings.warn(
[2022-03-03 19:33:30,885] {http_hook.py:150} ERROR - HTTP error: Too Many Requests
[2022-03-03 19:33:30,885] {http_hook.py:151} ERROR - {"title":"Too Many Requests","detail":"Too Many Requests","type":"about:blank","status":429}
[2022-03-03 19:33:30,887] {taskinstance.py:1150} ERROR - 429:Too Many Requests
Traceback (most recent call last):
  File "/run/datapipeline/.env/lib/python3.8/site-packages/airflow/hooks/http_hook.py", line 148, in check_response
    response.raise_for_status()
  File "/run/datapipeline/.env/lib/python3.8/site-packages/requests/models.py", line 941, in raise_for_status
    raise HTTPError(http_error_msg, response=self)
requests.exceptions.HTTPError: 429 Client Error: Too Many Requests for url: https://api.twitter.com/2/tweets/search/recent?query=jade&tweet.fields=author_id,conversation_id,created_at,id,in_reply_to_user_id,public_metrics,text&expansions=author_id&user.fields=id,name,username,created_at&start_time=2022-02-26T09:00:00.00Z&end_time=2022-02-27T09:00:00.00Z

During handling of the above exception, another exception occurred:

Traceback (most recent call last):
  File "/run/datapipeline/.env/lib/python3.8/site-packages/airflow/models/taskinstance.py", line 984, in _run_raw_task
    result = task_copy.execute(context=context)
  File "/run/datapipeline/airflow/plugins/operators/twitter_operator.py", line 52, in execute
    for pg in hook.run():
  File "/run/datapipeline/airflow/plugins/hooks/twitter_hook.py", line 56, in run
    yield from self.paginate(url, session)
  File "/run/datapipeline/airflow/plugins/hooks/twitter_hook.py", line 45, in paginate
    data = self.connect_to_endpoint(full_url, session)
  File "/run/datapipeline/airflow/plugins/hooks/twitter_hook.py", line 37, in connect_to_endpoint
    return self.run_and_check(session, prep, {}).json()
  File "/run/datapipeline/.env/lib/python3.8/site-packages/airflow/hooks/http_hook.py", line 181, in run_and_check
    self.check_response(response)
  File "/run/datapipeline/.env/lib/python3.8/site-packages/airflow/hooks/http_hook.py", line 152, in check_response
    raise AirflowException(str(response.status_code) + ":" + response.reason)
airflow.exceptions.AirflowException: 429:Too Many Requests
[2022-03-03 19:33:30,889] {taskinstance.py:1187} INFO - Marking task as FAILED. dag_id=twitter_dag, task_id=twitter_bbb22, execution_date=20220226T090000, start_date=20220303T193330, end_date=20220303T193330
[2022-03-03 19:33:35,607] {local_task_job.py:102} INFO - Task exited with return code 1
[2022-03-03 19:55:24,126] {taskinstance.py:670} INFO - Dependencies all met for <TaskInstance: twitter_dag.twitter_bbb22 2022-02-26T09:00:00+00:00 [queued]>
[2022-03-03 19:55:24,133] {taskinstance.py:670} INFO - Dependencies all met for <TaskInstance: twitter_dag.twitter_bbb22 2022-02-26T09:00:00+00:00 [queued]>
[2022-03-03 19:55:24,133] {taskinstance.py:880} INFO - 
--------------------------------------------------------------------------------
[2022-03-03 19:55:24,133] {taskinstance.py:881} INFO - Starting attempt 1 of 1
[2022-03-03 19:55:24,133] {taskinstance.py:882} INFO - 
--------------------------------------------------------------------------------
[2022-03-03 19:55:24,139] {taskinstance.py:901} INFO - Executing <Task(TwitterOperator): twitter_bbb22> on 2022-02-26T09:00:00+00:00
[2022-03-03 19:55:24,141] {standard_task_runner.py:54} INFO - Started process 26593 to run task
[2022-03-03 19:55:24,175] {standard_task_runner.py:77} INFO - Running: ['airflow', 'run', 'twitter_dag', 'twitter_bbb22', '2022-02-26T09:00:00+00:00', '--job_id', '33', '--pool', 'default_pool', '--raw', '-sd', 'DAGS_FOLDER/twitter_dag.py', '--cfg_path', '/tmp/tmprlix1iqi']
[2022-03-03 19:55:24,176] {standard_task_runner.py:78} INFO - Job 33: Subtask twitter_bbb22
[2022-03-03 19:55:24,192] {logging_mixin.py:112} INFO - Running <TaskInstance: twitter_dag.twitter_bbb22 2022-02-26T09:00:00+00:00 [running]> on host 1a222f561522
[2022-03-03 19:55:24,223] {base_hook.py:89} INFO - Using connection to: id: twitter_default. Host: https://api.twitter.com, Port: None, Schema: None, Login: None, Password: None, extra: XXXXXXXX
[2022-03-03 19:55:24,224] {twitter_hook.py:36} INFO - URL: https://api.twitter.com/2/tweets/search/recent?query=jade&tweet.fields=author_id,conversation_id,created_at,id,in_reply_to_user_id,public_metrics,text&expansions=author_id&user.fields=id,name,username,created_at&start_time=2022-02-26T09:00:00.00Z&end_time=2022-02-27T09:00:00.00Z
[2022-03-03 19:55:24,253] {logging_mixin.py:112} WARNING - /run/datapipeline/.env/lib/python3.8/site-packages/urllib3/connectionpool.py:981: InsecureRequestWarning: Unverified HTTPS request is being made to host 'api.twitter.com'. Adding certificate verification is strongly advised. See: https://urllib3.readthedocs.io/en/latest/advanced-usage.html#ssl-warnings
  warnings.warn(
[2022-03-03 19:55:24,402] {http_hook.py:150} ERROR - HTTP error: Too Many Requests
[2022-03-03 19:55:24,402] {http_hook.py:151} ERROR - {"title":"Too Many Requests","detail":"Too Many Requests","type":"about:blank","status":429}
[2022-03-03 19:55:24,404] {taskinstance.py:1150} ERROR - 429:Too Many Requests
Traceback (most recent call last):
  File "/run/datapipeline/.env/lib/python3.8/site-packages/airflow/hooks/http_hook.py", line 148, in check_response
    response.raise_for_status()
  File "/run/datapipeline/.env/lib/python3.8/site-packages/requests/models.py", line 941, in raise_for_status
    raise HTTPError(http_error_msg, response=self)
requests.exceptions.HTTPError: 429 Client Error: Too Many Requests for url: https://api.twitter.com/2/tweets/search/recent?query=jade&tweet.fields=author_id,conversation_id,created_at,id,in_reply_to_user_id,public_metrics,text&expansions=author_id&user.fields=id,name,username,created_at&start_time=2022-02-26T09:00:00.00Z&end_time=2022-02-27T09:00:00.00Z

During handling of the above exception, another exception occurred:

Traceback (most recent call last):
  File "/run/datapipeline/.env/lib/python3.8/site-packages/airflow/models/taskinstance.py", line 984, in _run_raw_task
    result = task_copy.execute(context=context)
  File "/run/datapipeline/airflow/plugins/operators/twitter_operator.py", line 52, in execute
    for pg in hook.run():
  File "/run/datapipeline/airflow/plugins/hooks/twitter_hook.py", line 56, in run
    yield from self.paginate(url, session)
  File "/run/datapipeline/airflow/plugins/hooks/twitter_hook.py", line 45, in paginate
    data = self.connect_to_endpoint(full_url, session)
  File "/run/datapipeline/airflow/plugins/hooks/twitter_hook.py", line 37, in connect_to_endpoint
    return self.run_and_check(session, prep, {}).json()
  File "/run/datapipeline/.env/lib/python3.8/site-packages/airflow/hooks/http_hook.py", line 181, in run_and_check
    self.check_response(response)
  File "/run/datapipeline/.env/lib/python3.8/site-packages/airflow/hooks/http_hook.py", line 152, in check_response
    raise AirflowException(str(response.status_code) + ":" + response.reason)
airflow.exceptions.AirflowException: 429:Too Many Requests
[2022-03-03 19:55:24,405] {taskinstance.py:1187} INFO - Marking task as FAILED. dag_id=twitter_dag, task_id=twitter_bbb22, execution_date=20220226T090000, start_date=20220303T195524, end_date=20220303T195524
[2022-03-03 19:55:29,123] {local_task_job.py:102} INFO - Task exited with return code 1
[2022-03-03 20:14:46,039] {taskinstance.py:670} INFO - Dependencies all met for <TaskInstance: twitter_dag.twitter_bbb22 2022-02-26T09:00:00+00:00 [queued]>
[2022-03-03 20:14:46,048] {taskinstance.py:670} INFO - Dependencies all met for <TaskInstance: twitter_dag.twitter_bbb22 2022-02-26T09:00:00+00:00 [queued]>
[2022-03-03 20:14:46,048] {taskinstance.py:880} INFO - 
--------------------------------------------------------------------------------
[2022-03-03 20:14:46,048] {taskinstance.py:881} INFO - Starting attempt 1 of 1
[2022-03-03 20:14:46,048] {taskinstance.py:882} INFO - 
--------------------------------------------------------------------------------
[2022-03-03 20:14:46,062] {taskinstance.py:901} INFO - Executing <Task(TwitterOperator): twitter_bbb22> on 2022-02-26T09:00:00+00:00
[2022-03-03 20:14:46,064] {standard_task_runner.py:54} INFO - Started process 9675 to run task
[2022-03-03 20:14:46,119] {standard_task_runner.py:77} INFO - Running: ['airflow', 'run', 'twitter_dag', 'twitter_bbb22', '2022-02-26T09:00:00+00:00', '--job_id', '35', '--pool', 'default_pool', '--raw', '-sd', 'DAGS_FOLDER/twitter_dag.py', '--cfg_path', '/tmp/tmpmwa3q998']
[2022-03-03 20:14:46,120] {standard_task_runner.py:78} INFO - Job 35: Subtask twitter_bbb22
[2022-03-03 20:14:46,142] {logging_mixin.py:112} INFO - Running <TaskInstance: twitter_dag.twitter_bbb22 2022-02-26T09:00:00+00:00 [running]> on host 1a222f561522
[2022-03-03 20:14:46,190] {base_hook.py:89} INFO - Using connection to: id: twitter_default. Host: https://api.twitter.com, Port: None, Schema: None, Login: None, Password: None, extra: XXXXXXXX
[2022-03-03 20:14:46,193] {twitter_hook.py:36} INFO - URL: https://api.twitter.com/2/tweets/search/recent?query=jade&tweet.fields=author_id,conversation_id,created_at,id,in_reply_to_user_id,public_metrics,text&expansions=author_id&user.fields=id,name,username,created_at&start_time=2022-02-26T09:00:00.00Z&end_time=2022-02-27T09:00:00.00Z
[2022-03-03 20:14:46,217] {logging_mixin.py:112} WARNING - /run/datapipeline/.env/lib/python3.8/site-packages/urllib3/connectionpool.py:981: InsecureRequestWarning: Unverified HTTPS request is being made to host 'api.twitter.com'. Adding certificate verification is strongly advised. See: https://urllib3.readthedocs.io/en/latest/advanced-usage.html#ssl-warnings
  warnings.warn(
[2022-03-03 20:14:46,361] {http_hook.py:150} ERROR - HTTP error: Too Many Requests
[2022-03-03 20:14:46,361] {http_hook.py:151} ERROR - {"title":"Too Many Requests","detail":"Too Many Requests","type":"about:blank","status":429}
[2022-03-03 20:14:46,364] {taskinstance.py:1150} ERROR - 429:Too Many Requests
Traceback (most recent call last):
  File "/run/datapipeline/.env/lib/python3.8/site-packages/airflow/hooks/http_hook.py", line 148, in check_response
    response.raise_for_status()
  File "/run/datapipeline/.env/lib/python3.8/site-packages/requests/models.py", line 941, in raise_for_status
    raise HTTPError(http_error_msg, response=self)
requests.exceptions.HTTPError: 429 Client Error: Too Many Requests for url: https://api.twitter.com/2/tweets/search/recent?query=jade&tweet.fields=author_id,conversation_id,created_at,id,in_reply_to_user_id,public_metrics,text&expansions=author_id&user.fields=id,name,username,created_at&start_time=2022-02-26T09:00:00.00Z&end_time=2022-02-27T09:00:00.00Z

During handling of the above exception, another exception occurred:

Traceback (most recent call last):
  File "/run/datapipeline/.env/lib/python3.8/site-packages/airflow/models/taskinstance.py", line 984, in _run_raw_task
    result = task_copy.execute(context=context)
  File "/run/datapipeline/airflow/plugins/operators/twitter_operator.py", line 52, in execute
    for pg in hook.run():
  File "/run/datapipeline/airflow/plugins/hooks/twitter_hook.py", line 56, in run
    yield from self.paginate(url, session)
  File "/run/datapipeline/airflow/plugins/hooks/twitter_hook.py", line 45, in paginate
    data = self.connect_to_endpoint(full_url, session)
  File "/run/datapipeline/airflow/plugins/hooks/twitter_hook.py", line 37, in connect_to_endpoint
    return self.run_and_check(session, prep, {}).json()
  File "/run/datapipeline/.env/lib/python3.8/site-packages/airflow/hooks/http_hook.py", line 181, in run_and_check
    self.check_response(response)
  File "/run/datapipeline/.env/lib/python3.8/site-packages/airflow/hooks/http_hook.py", line 152, in check_response
    raise AirflowException(str(response.status_code) + ":" + response.reason)
airflow.exceptions.AirflowException: 429:Too Many Requests
[2022-03-03 20:14:46,366] {taskinstance.py:1187} INFO - Marking task as FAILED. dag_id=twitter_dag, task_id=twitter_bbb22, execution_date=20220226T090000, start_date=20220303T201446, end_date=20220303T201446
[2022-03-03 20:14:51,028] {local_task_job.py:102} INFO - Task exited with return code 1
